Workbook

Sheet Benchmark Log
A1: Benchmark Log
A3: tier | B3: tier_name | C3: engine | D3: query_name | E3: query_type | F3: Time | G3: node_spec | H3: notes
A4: 0 | B4: =IFERROR(INDEX('Tier Reference'!$B:$B,MATCH(A4,'Tier Reference'!$A:$A,0)),"") -> Data Preparation (download, sample, S3 upload etc) | C4: curl | D4: DOWNLOAD | E4: data-prep | F4: 41 | G4: EC2 t3.medium | H4: Full ~30GB source file download from Kaggle
A5: 0 | C5: aws-cli | D5: S3_UPLOAD_FULL | E5: data-prep | F5: 238 | G5: EC2 t3.medium | H5: Uploading full source file to S3 Bucket for future use, steady 128MiB/s
A6: 0 | C6: awk | D6: SAMPLE | E6: data-prep | F6: 351 | G6: EC2 t3.medium | H6: Single-pass, single-threaded interlaced sample of full 29GB CSV, keeping header + every even-numbered line
A7: 0 | C7: md5sum | D7: CHECKSUM | E7: data-prep | F7: 117 | G7: EC2 t3.medium | H7: Two spot-checks (sample line 5 vs original line 8, sample line 100 vs original line 198) both confirmed exact match
A8: 0 | C8: aws-cli | D8: S3_UPLOAD_SAMPLE | E8: data-prep | F8: 119 | G8: EC2 t3.medium | H8: Upload of verified 15GB sampled dataset to S3, steady 128MiB/s
A9: 0 | C9: MySQL | D9: MYSQL_LOAD_FULL | E9: data-prep | F9: 2526 | G9: Local Machine | H9: Upload of full dataset to MYSQL Table, around 28MB/s read in s
A10: 0 | C10: MySQL | D10: MYSQL_FILTER | E10: data-prep | F10: 2550 | G10: Local Machine | H10: Filter dataset to MYSQL, around 178MB RAM used and 40-50 MB/s disk usage
A11: 0 | C11: MySQL | D11: MYSQL_EXPORT | E11: data-prep | F11: 6540 | G11: Local Machine | H11: Exporting MYSQL filtered sample to CSV, the default memory allocation was not enough, had to manually allocate 8GB of RAM to the task
A12: 0 | C12: MySQL | D12: MYSQL_VERIFY_ROWS | E12: data-prep | F12: 30.91 | G12: Local Machine | H12: Select count from flights table to verify that all rows from sample dataset is present before continuing
A13: 0 | C13: MySQL | D13: Create_Sequential_ID | E13: Schema change | F13: 8194.53 | G13: Local Machine | H13: Since legID has duplicates, create new column id to auto increment and act as index
A14: 0 | C14: MySQL | D14: Create_Index_legid | E14: Schema change | F14: 328.14 | G14: Local Machine | H14: Create INDEX based on id
A15: 0 | C15: MySQL | D15: Create_Index_route | E15: Schema change | F15: 297.07 | G15: Local Machine | H15: Create INDEX based on Airport start and destination pair as well as flight date
A16: 0 | C16: MySQL | D16: Create_Index_fare | E16: Schema change | F16: 211.48 | G16: Local Machine | H16: Create INDEX based on fare
... A23: 0 | C23: Postgres | D23: Create_Index_all | E23: Schema change | F23: 1090.53 | G23: Local Machine | H23: PK (BIGSERIAL) + idx_legid, idx_route_date, idx_fare, combined single timing
A24: 1 | B24: =IFERROR(INDEX('Tier Reference'!$B:$B,MATCH(A24,'Tier Reference'!$A:$A,0)),"") -> MySQL vanilla (no index) | C24: MySQL | D24: QUERY1 | E24: Single row | F24: 77 | G24: Local Machine | H24: Full table scan to find 1 row
A25: 1 | C25: MySQL | D25: QUERY2 | E25: Range | F25: 125 | G25: Local Machine | H25: JFK to LAX under 300 in June
A26: 1 | C26: MySQL | D26: QUERY3 | E26: Aggregation | F26: 284 | G26: Local Machine | H26: Average fare per route per month
A27: 1 | C27: MySQL | D27: QUERY4 | E27: Join | F27: 89 | G27: Local Machine | H27: Average fare non stop vs connecting
A28: 1 | C28: MySQL | D28: QUERY5 | E28: Single write | F28: 0.05 | G28: Local Machine | H28: Insert 1 synthethic row
A29: 1 | C29: MySQL | D29: QUERY6 | E29: Range write | F29: 108 | G29: Local Machine | H29: Update seatsRemaining for ATL on July 4th
A30: 2 | B30: =IFERROR(INDEX('Tier Reference'!$B:$B,MATCH(A30,'Tier Reference'!$A:$A,0)),"") -> MySQL indexed (+partitioned) | C30: MySQL | D30: QUERY1 | E30: Single row | F30: 0.01 | G30: Local Machine | H30: Index_legid used, down from 84.55 seconds in Tier1
A31: 2 | C31: MySQL | D31: QUERY2 | E31: Range | F31: 0.25 | G31: Local Machine | H31: Index_route used, down from 78.62 in Tier1
A32: 2 | C32: MySQL | D32: QUERY3 | E32: Aggregation | F32: 423.06 | G32: Local Machine | H32: Index unable to be used, group by on flight date is on year and month and cant be used without first creating and populating a new computed column which will not be done for this tier, the additional indexing has already slowed down querying compared to Tier1
A33: 2 | C33: MySQL | D33: QUERY4 | E33: Join | F33: 154.92 | G33: Local Machine | H33: Index not used efficiently, the indexing does not cover full table group by without an additional covering index, not implemented for this tier
A34: 2 | C34: MySQL | D34: QUERY5 | E34: Single write | F34: 0.02 | G34: Local Machine | H34: Insert 1 synthetic row
A35: 2 | C35: MySQL | D35: QUERY6 | E35: Range write | F35: 211.03 | G35: Local Machine | H35: MYSQL chose index type full over Index_route, since it might not be selective enough for the optimizer to prefer an index lookup over full scan, slower as the update would need to maintain the four indexes on every row changed, on top the the full scan cost
A36: 3 | B36: =IFERROR(INDEX('Tier Reference'!$B:$B,MATCH(A36,'Tier Reference'!$A:$A,0)),"") -> DuckDB | C36: duckdb | D36: QUERY1 | E36: Single row | F36: 8.6369 | G36: Local Machine | H36: Point lookup by legId, 1 row returned
A37: 3 | C37: duckdb | D37: QUERY2 | E37: Range | F37: 29.7747 | G37: Local Machine | H37: JFK to LAX under $300 in June, 3421 rows returned
A38: 3 | C38: duckdb | D38: QUERY3 | E38: Aggregation | F38: 10.0253 | G38: Local Machine | H38: Average fare per route per month, 1873 rows returned
A39: 3 | C39: duckdb | D39: QUERY4 | E39: Aggregation | F39: 1.6579 | G39: Local Machine | H39: Average fare non-stop vs connecting, 450 rows returned
A40: 3 | C40: duckdb | D40: QUERY5 | E40: Single write | F40: 0.1141 | G40: Local Machine | H40: Insert 1 synthetic row
A41: 3 | C41: duckdb | D41: QUERY6 | E41: Range write | F41: 0.3028 | G41: Local Machine | H41: Update seatsRemaining for ATL on July 4th
A42: 4 | B42: =IFERROR(INDEX('Tier Reference'!$B:$B,MATCH(A42,'Tier Reference'!$A:$A,0)),"") -> Postgres | C42: =IFERROR(INDEX('Tier Reference'!$B:$B,MATCH(A42,'Tier Reference'!$A:$A,0)),"") -> Postgres | D42: QUERY1 | E42: Single row | F42: 0.0098 | G42: Local Machine
A43: 4 | C43: =IFERROR(INDEX('Tier Reference'!$B:$B,MATCH(A43,'Tier Reference'!$A:$A,0)),"") -> Postgres | D43: QUERY2 | E43: Range | F43: 0.92 | G43: Local Machine
A44: 4 | C44: =IFERROR(INDEX('Tier Reference'!$B:$B,MATCH(A44,'Tier Reference'!$A:$A,0)),"") -> Postgres | D44: QUERY3 | E44: Aggregation | F44: 240.27 | G44: Local Machine
A45: 4 | C45: =IFERROR(INDEX('Tier Reference'!$B:$B,MATCH(A45,'Tier Reference'!$A:$A,0)),"") -> Postgres | D45: QUERY4 | E45: Join | F45: 23.22 | G45: Local Machine
A46: 4 | C46: =IFERROR(INDEX('Tier Reference'!$B:$B,MATCH(A46,'Tier Reference'!$A:$A,0)),"") -> Postgres | D46: QUERY5 | E46: Single write | F46: 0.02 | G46: Local Machine
A47: 4 | C47: =IFERROR(INDEX('Tier Reference'!$B:$B,MATCH(A47,'Tier Reference'!$A:$A,0)),"") -> Postgres | D47: QUERY6 | E47: Range write | F47: 3.43 | G47: Local Machine
...

Sheet Legend
A1: IST3134 Benchmark Results
A3: Column | B3: Meaning | C3: Example
A4: tier | B4: Tier number, 0-12, matching the instructions doc | C4: 0
A5: tier_name | B5: Auto-filled from the Tier Reference tab | C5: MySQL vanilla (no index)
A6: engine | B6: Specific engine/tool used within that tier | C6: mysql, postgres, duckdb-csv, duckdb-table, mapreduce-streaming, spark-yarn, spark-emr, hive, athena-csv, athena-parquet, athena-iceberg, bigquery
A7: query_id | B7: Q1-Q6 per the fixed benchmark workload, or LOAD / INDEX_BUILD for one-off setup timings | C7: Q3
A8: query_type | B8: single-row / range / aggregation / join / single-write / range-write / setup | C8: aggregation
A9: time | B9: Measured end-to-end time for that query, in seconds | C9: 812.40
A10: node_spec | B10: Hardware used | C10: 1x m5.xlarge
A11: notes | B11: Anything unusual: retries, errors, config tweaks | C11: 3rd run after 2 failed OOM attempts at default executor memory

Sheet Tier Reference
A1: Tier Reference
A3: tier | B3: tier_name | C3: purpose
A4: 0 | B4: Data Preparation (download, sample, S3 upload etc) | C4: One-time cost of building the dataset itself
A5: 1 | B5: MySQL vanilla (no index) | C5: Baseline
A6: 2 | B6: MySQL indexed (+partitioned) | C6: Isolates the effect of indexing/partitioning alone
A7: 3 | B7: DuckDB | C7: Modern local columnar engine
A8: 4 | B8: Postgres | C8: Modern indexed row store
A9: 5 | B9: Self-managed Hadoop MapReduce | C9: Historical distributed batch baseline
A10: 6 | B10: Self-managed Spark on YARN | C10: Spark vs MapReduce, same hardware
A11: 7 | B11: Single EMR node | C11: Managed service overhead vs self-managed
A12: 8 | B12: Larger EMR node | C12: Vertical scaling test, with one node with more RAM
A13: 9 | B13: Multi-node EMR cluster | C13: Horizontal scaling test, resource-matched to Tier 7
A14: 10 | B14: Spark SQL / DataFrames (joins, windows) | C14: Explicit query-layer explanation
A15: 11 | B15: Lakehouse: S3 + Glue + Iceberg | C15: ACID single-write / range-write demonstration
... A17: 13 | B17: Hive vs Spark SQL on EMR | C17: Isolates query engine, same cluster/data
